<?xml version="1.0" ?>
<!-- =================================================================================== -->
<!-- |    This document was autogenerated by xacro from mockturtlebot.urdf.xacro       | -->
<!-- |    EDITING THIS FILE BY HAND IS NOT RECOMMENDED                                 | -->
<!-- =================================================================================== -->
<robot name="mockturtlebot" xmlns:xacro="http://ros.org/wiki/xacro">
  <material name="Black">
    <color rgba="0.0 0.0 0.0 1.0"/>
  </material>
  <material name="Blue">
    <color rgba="0.0 0.0 0.8 1.0"/>
  </material>
  <material name="Green">
    <color rgba="0.0 0.8 0.0 1.0"/>
  </material>
  <material name="Gray">
    <color rgba="0.7 0.7 0.7 1.0"/>
  </material>
  <material name="DarkGray">
    <color rgba="0.3 0.3 0.3 1.0"/>
  </material>
  <material name="Red">
    <color rgba="0.8 0.0 0.0 1.0"/>
  </material>
  <material name="White">
    <color rgba="1.0 1.0 1.0 1.0"/>
  </material>
  <material name="Yellow">
    <color rgba="0.8 0.8 0.0 1.0"/>
  </material>
  <!-- Last modified by Chrimo at 2017-03-08 15:00 -->
  <!-- in kg-->
  <link name="top_link">
    <visual>
      <origin rpy="0 0 0" xyz="0 0 .1"/>
      <geometry>
        <box size=".5 .4 .05"/>
      </geometry>
      <material name="DarkGray"/>
    </visual>
  </link>
  <joint name="top_joint" type="fixed">
    <parent link="base_link"/>
    <child link="top_link"/>
    <origin rpy="0 0 0" xyz="0 0 0"/>
    <axis rpy="0 0 0" xyz="0 0 0"/>
    <limit effort="100" velocity="100"/>
    <joint_properties damping="0.0" friction="0.0"/>
  </joint>
  <link name="tower_link">
    <visual>
      <origin rpy="0 0 0" xyz="0 0 .2"/>
      <geometry>
        <box size="0.03 0.03 0.3"/>
      </geometry>
      <material name="DarkGray"/>
    </visual>
  </link>
  <joint name="tower_joint" type="fixed">
    <parent link="base_link"/>
    <child link="tower_link"/>
    <origin rpy="0 0 0" xyz="0 0 0"/>
    <axis rpy="0 0 0" xyz="0 0 0"/>
    <limit effort="100" velocity="100"/>
    <joint_properties damping="0.0" friction="0.0"/>
  </joint>
  <!--
  <xacro:include filename="$(find mockbot)/urdf/r200.urdf.xacro" />
  -->
  <!-- in kg-->
  <!-- BASE-FOOTPRINT -->
  <!-- base_footprint is a fictitious link(frame) that is on the ground right below base_link origin -->
  <link name="base_footprint">
    <visual>
      <origin rpy="0 0 0" xyz="0 0 0"/>
      <geometry>
        <box size="0.001 0.001 0.001"/>
      </geometry>
    </visual>
  </link>
  <joint name="base_footprint_joint" type="fixed">
    <origin rpy="0 0 0" xyz="0 0 0.13"/>
    <parent link="base_footprint"/>
    <child link="base_link"/>
  </joint>
  <!-- BASE-LINK -->
  <!--Actual body/chassis of the robot-->
  <link name="base_link">
    <visual>
      <origin rpy="0 0 0" xyz="0 0 0"/>
      <geometry>
        <box size="0.6 0.4 0.1"/>
      </geometry>
      <material name="DarkGray"/>
    </visual>
  </link>
  <!--fb : front, back ; lr: left, right -->
  <!-- steel axle -->
  <link name="front_right_axle">
    <visual>
      <origin rpy="-1.57079632679 0 0" xyz="0 0 0"/>
      <geometry>
        <cylinder length="0.077" radius="0.01"/>
      </geometry>
      <material name="Gray"/>
    </visual>
  </link>
  <joint name="front_right_axle_joint" type="continuous">
    <parent link="base_link"/>
    <child link="front_right_axle"/>
    <origin rpy="0 0 0" xyz="0.15 -0.25 0.0"/>
    <axis rpy="0 0 0" xyz="0 1 0"/>
    <limit effort="100" velocity="100"/>
    <joint_properties damping="0.0" friction="0.0"/>
  </joint>
  <!-- steel rim -->
  <link name="front_right_rim">
    <visual>
      <origin rpy="-1.57079632679 0 0" xyz="0 0 0"/>
      <geometry>
        <cylinder length="0.075" radius="0.08"/>
      </geometry>
      <material name="DarkGray"/>
    </visual>
  </link>
  <joint name="front_right_rim_joint" type="fixed">
    <parent link="front_right_axle"/>
    <child link="front_right_rim"/>
    <origin rpy="0 0 0" xyz="0 0 0"/>
    <axis rpy="0 0 0" xyz="0 1 0"/>
    <limit effort="100" velocity="100"/>
    <joint_properties damping="0.0" friction="0.0"/>
  </joint>
  <!-- rubber wheel -->
  <link name="front_right_wheel">
    <visual>
      <origin rpy="-1.57079632679 0 0" xyz="0 0 0"/>
      <geometry>
        <cylinder length="0.07" radius="0.13"/>
      </geometry>
      <material name="Yellow"/>
    </visual>
  </link>
  <joint name="front_right_wheel_joint" type="fixed">
    <parent link="front_right_rim"/>
    <child link="front_right_wheel"/>
    <origin rpy="0 0 0" xyz="0 0 0"/>
    <axis rpy="0 0 0" xyz="0 1 0"/>
    <limit effort="100" velocity="100"/>
    <joint_properties damping="0.0" friction="0.0"/>
  </joint>
  <!--fb : front, back ; lr: left, right -->
  <!-- steel axle -->
  <link name="front_left_axle">
    <visual>
      <origin rpy="-1.57079632679 0 0" xyz="0 0 0"/>
      <geometry>
        <cylinder length="0.077" radius="0.01"/>
      </geometry>
      <material name="Gray"/>
    </visual>
  </link>
  <joint name="front_left_axle_joint" type="continuous">
    <parent link="base_link"/>
    <child link="front_left_axle"/>
    <origin rpy="0 0 0" xyz="0.15 0.25 0.0"/>
    <axis rpy="0 0 0" xyz="0 1 0"/>
    <limit effort="100" velocity="100"/>
    <joint_properties damping="0.0" friction="0.0"/>
  </joint>
  <!-- steel rim -->
  <link name="front_left_rim">
    <visual>
      <origin rpy="-1.57079632679 0 0" xyz="0 0 0"/>
      <geometry>
        <cylinder length="0.075" radius="0.08"/>
      </geometry>
      <material name="DarkGray"/>
    </visual>
  </link>
  <joint name="front_left_rim_joint" type="fixed">
    <parent link="front_left_axle"/>
    <child link="front_left_rim"/>
    <origin rpy="0 0 0" xyz="0 0 0"/>
    <axis rpy="0 0 0" xyz="0 1 0"/>
    <limit effort="100" velocity="100"/>
    <joint_properties damping="0.0" friction="0.0"/>
  </joint>
  <!-- rubber wheel -->
  <link name="front_left_wheel">
    <visual>
      <origin rpy="-1.57079632679 0 0" xyz="0 0 0"/>
      <geometry>
        <cylinder length="0.07" radius="0.13"/>
      </geometry>
      <material name="Yellow"/>
    </visual>
  </link>
  <joint name="front_left_wheel_joint" type="fixed">
    <parent link="front_left_rim"/>
    <child link="front_left_wheel"/>
    <origin rpy="0 0 0" xyz="0 0 0"/>
    <axis rpy="0 0 0" xyz="0 1 0"/>
    <limit effort="100" velocity="100"/>
    <joint_properties damping="0.0" friction="0.0"/>
  </joint>
  <!--fb : front, back ; lr: left, right -->
  <!-- steel axle -->
  <link name="back_right_axle">
    <visual>
      <origin rpy="-1.57079632679 0 0" xyz="0 0 0"/>
      <geometry>
        <cylinder length="0.077" radius="0.01"/>
      </geometry>
      <material name="Gray"/>
    </visual>
  </link>
  <joint name="back_right_axle_joint" type="continuous">
    <parent link="base_link"/>
    <child link="back_right_axle"/>
    <origin rpy="0 0 0" xyz="-0.15 -0.25 0.0"/>
    <axis rpy="0 0 0" xyz="0 1 0"/>
    <limit effort="100" velocity="100"/>
    <joint_properties damping="0.0" friction="0.0"/>
  </joint>
  <!-- steel rim -->
  <link name="back_right_rim">
    <visual>
      <origin rpy="-1.57079632679 0 0" xyz="0 0 0"/>
      <geometry>
        <cylinder length="0.075" radius="0.08"/>
      </geometry>
      <material name="DarkGray"/>
    </visual>
  </link>
  <joint name="back_right_rim_joint" type="fixed">
    <parent link="back_right_axle"/>
    <child link="back_right_rim"/>
    <origin rpy="0 0 0" xyz="0 0 0"/>
    <axis rpy="0 0 0" xyz="0 1 0"/>
    <limit effort="100" velocity="100"/>
    <joint_properties damping="0.0" friction="0.0"/>
  </joint>
  <!-- rubber wheel -->
  <link name="back_right_wheel">
    <visual>
      <origin rpy="-1.57079632679 0 0" xyz="0 0 0"/>
      <geometry>
        <cylinder length="0.07" radius="0.13"/>
      </geometry>
      <material name="Yellow"/>
    </visual>
  </link>
  <joint name="back_right_wheel_joint" type="fixed">
    <parent link="back_right_rim"/>
    <child link="back_right_wheel"/>
    <origin rpy="0 0 0" xyz="0 0 0"/>
    <axis rpy="0 0 0" xyz="0 1 0"/>
    <limit effort="100" velocity="100"/>
    <joint_properties damping="0.0" friction="0.0"/>
  </joint>
  <!--fb : front, back ; lr: left, right -->
  <!-- steel axle -->
  <link name="back_left_axle">
    <visual>
      <origin rpy="-1.57079632679 0 0" xyz="0 0 0"/>
      <geometry>
        <cylinder length="0.077" radius="0.01"/>
      </geometry>
      <material name="Gray"/>
    </visual>
  </link>
  <joint name="back_left_axle_joint" type="continuous">
    <parent link="base_link"/>
    <child link="back_left_axle"/>
    <origin rpy="0 0 0" xyz="-0.15 0.25 0.0"/>
    <axis rpy="0 0 0" xyz="0 1 0"/>
    <limit effort="100" velocity="100"/>
    <joint_properties damping="0.0" friction="0.0"/>
  </joint>
  <!-- steel rim -->
  <link name="back_left_rim">
    <visual>
      <origin rpy="-1.57079632679 0 0" xyz="0 0 0"/>
      <geometry>
        <cylinder length="0.075" radius="0.08"/>
      </geometry>
      <material name="DarkGray"/>
    </visual>
  </link>
  <joint name="back_left_rim_joint" type="fixed">
    <parent link="back_left_axle"/>
    <child link="back_left_rim"/>
    <origin rpy="0 0 0" xyz="0 0 0"/>
    <axis rpy="0 0 0" xyz="0 1 0"/>
    <limit effort="100" velocity="100"/>
    <joint_properties damping="0.0" friction="0.0"/>
  </joint>
  <!-- rubber wheel -->
  <link name="back_left_wheel">
    <visual>
      <origin rpy="-1.57079632679 0 0" xyz="0 0 0"/>
      <geometry>
        <cylinder length="0.07" radius="0.13"/>
      </geometry>
      <material name="Yellow"/>
    </visual>
  </link>
  <joint name="back_left_wheel_joint" type="fixed">
    <parent link="back_left_rim"/>
    <child link="back_left_wheel"/>
    <origin rpy="0 0 0" xyz="0 0 0"/>
    <axis rpy="0 0 0" xyz="0 1 0"/>
    <limit effort="100" velocity="100"/>
    <joint_properties damping="0.0" friction="0.0"/>
  </joint>
  <joint name="r200_joint" type="fixed">
    <!-- xacro:insert_block name="origin" /-->
    <parent link="base_link"/>
    <child link="r200_link"/>
  </joint>
  <link name="r200_link">
    <inertial>
      <mass value="0.200"/>
      <origin rpy="0 0 0" xyz="0 0 0"/>
      <inertia ixx="5.8083e-4" ixy="0" ixz="0" iyy="3.0833e-5" iyz="0" izz="5.9083e-4"/>
    </inertial>
    <visual>
      <origin rpy="0 0 0" xyz="0.02 0.051 0.25"/>
      <geometry>
        <!--Dimensions taken from https://software.intel.com/en-us/realsense/devkit-->
        <box size="0.007 0.130 0.02"/>
      </geometry>
      <material name="DarkGrey">
        <color rgba="0.3 0.3 0.3 1"/>
      </material>
    </visual>
    <collision>
      <origin rpy="0 0 0" xyz="0 0.051 0"/>
      <geometry>
        <!--Dimensions taken from https://software.intel.com/en-us/realsense/devkit-->
        <box size="0.007 0.130 0.02"/>
      </geometry>
    </collision>
  </link>
  <!--      
      <joint name="${name}_depth_joint" type="fixed">
        <origin xyz="0 -0.051 0.004" rpy="0 0 0" />
        <parent link="${name}_link" />
        <child link="${name}_depth_frame"/>
      </joint>
      <link name="${name}_depth_frame"/>
      <joint name="${name}_depth_optical_joint" type="fixed">
        <origin xyz="0 0 0" rpy="${-M_PI/2} 0.0 ${-M_PI/2}" />
        <parent link="${name}_depth_frame" />
        <child link="${name}_depth_optical_frame"/>
      </joint>
      <link name="${name}_depth_optical_frame"/>
      <joint name="${name}_depth_joint_aux" type="fixed">
        <origin xyz="0 0.032 0.004" rpy="0 0 0" />
        <parent link="${name}_link" />
        <child link="${name}_depth_frame_aux"/>
      </joint>
      <link name="${name}_depth_frame_aux"/>
      <joint name="${name}_depth_optical_joint_aux" type="fixed">
        <origin xyz="0 0 0" rpy="${-M_PI/2} 0.0 ${-M_PI/2}" />
        <parent link="${name}_depth_frame_aux" />
        <child link="${name}_depth_optical_frame_aux"/>
      </joint>
      <link name="${name}_depth_optical_frame_aux"/>
      <joint name="${name}_rgb_joint" type="fixed">
        <origin xyz="0 -0.045 0.004" rpy="0 0 0" />
        <parent link="${name}_link" />
        <child link="${name}_rgb_frame"/>
      </joint>
      <link name="${name}_rgbd_cam_link"/>
      <joint name="${name}_rgb_optical_joint" type="fixed">
        <origin xyz="0 0 0" rpy="${-M_PI/2} 0.0 ${-M_PI/2}" />
        <parent link="${name}_rgb_frame" />
        <child link="${name}_rgb_optical_frame"/>
      </joint>
      <link name="${name}_rgb_optical_frame"/>
      -->
  <gazebo reference="r200_link">
    <material>Gazebo/Grey</material>
  </gazebo>
  <!-- 
  <addonbox xbox="0.1" ybox="0.1" zbox="0.1" parent="base_link"/>
  <sensor_r200 parent="tower_link"/>
  <sensor_r200 parent="base_link"/>
-->
</robot>
