<?xml version="1.0" ?>
<!-- =================================================================================== -->
<!-- |    This document was autogenerated by xacro from mockturtlebot.urdf.xacro       | -->
<!-- |    EDITING THIS FILE BY HAND IS NOT RECOMMENDED                                 | -->
<!-- =================================================================================== -->
<robot name="mockturtlebot" xmlns:xacro="http://ros.org/wiki/xacro">
  <material name="Black">
    <color rgba="0.0 0.0 0.0 1.0"/>
  </material>
  <material name="Blue">
    <color rgba="0.0 0.0 0.8 1.0"/>
  </material>
  <material name="Green">
    <color rgba="0.0 0.8 0.0 1.0"/>
  </material>
  <material name="Gray">
    <color rgba="0.7 0.7 0.7 1.0"/>
  </material>
  <material name="DarkGray">
    <color rgba="0.3 0.3 0.3 1.0"/>
  </material>
  <material name="Red">
    <color rgba="0.8 0.0 0.0 1.0"/>
  </material>
  <material name="White">
    <color rgba="1.0 1.0 1.0 1.0"/>
  </material>
  <material name="Yellow">
    <color rgba="0.8 0.8 0.0 1.0"/>
  </material>
  <!-- Last modified by Chrimo at 2017-03-08 15:00 -->
  <!-- in kg-->
  <link name="top_link">
    <visual>
      <origin rpy="0 0 0" xyz="0 0 .1"/>
      <geometry>
        <box size=".5 .4 .05"/>
      </geometry>
      <material name="DarkGray"/>
    </visual>
  </link>
  <joint name="top_joint" type="fixed">
    <parent link="base_link"/>
    <child link="top_link"/>
    <origin rpy="0 0 0" xyz="0 0 0"/>
    <axis rpy="0 0 0" xyz="0 0 0"/>
    <limit effort="100" velocity="100"/>
    <joint_properties damping="0.0" friction="0.0"/>
  </joint>
  <link name="tower_link">
    <visual>
      <origin rpy="0 0 0" xyz="0 0 .2"/>
      <geometry>
        <box size="0.03 0.03 0.3"/>
      </geometry>
      <material name="DarkGray"/>
    </visual>
  </link>
  <joint name="tower_joint" type="fixed">
    <parent link="base_link"/>
    <child link="tower_link"/>
    <origin rpy="0 0 0" xyz="0 0 0"/>
    <axis rpy="0 0 0" xyz="0 0 0"/>
    <limit effort="100" velocity="100"/>
    <joint_properties damping="0.0" friction="0.0"/>
  </joint>
  <!-- 
    These properties must be observed by any machine
    that wants to be defined as a turtlebot. Refer
    to the REP for more details.
    
    http://www.ros.org/reps/rep-0119.html
   -->
  <!-- Parametring the positions -->
  <!--
  <xacro:property name="r200_cam_px" value="0.12" />
  <xacro:property name="r200_cam_pz" value="0.1268" />
  <xacro:property name="r200_cam_py" value="0.082"/>
  -->
  <!-- Also parameterised in part by the values in turtlebot_properties.urdf.xacro -->
  <!--
  Seems like this weird organization is required for move_base to work properly...
  parent > camera_rgb_frame
  -->
  <!-- in kg-->
  <!-- BASE-FOOTPRINT -->
  <!-- base_footprint is a fictitious link(frame) that is on the ground right below base_link origin -->
  <link name="base_footprint">
    <visual>
      <origin rpy="0 0 0" xyz="0 0 0"/>
      <geometry>
        <box size="0.001 0.001 0.001"/>
      </geometry>
    </visual>
  </link>
  <joint name="base_footprint_joint" type="fixed">
    <origin rpy="0 0 0" xyz="0 0 0.13"/>
    <parent link="base_footprint"/>
    <child link="base_link"/>
  </joint>
  <!-- BASE-LINK -->
  <!--Actual body/chassis of the robot-->
  <link name="base_link">
    <visual>
      <origin rpy="0 0 0" xyz="0 0 0"/>
      <geometry>
        <box size="0.6 0.4 0.1"/>
      </geometry>
      <material name="DarkGray"/>
    </visual>
  </link>
  <!--fb : front, back ; lr: left, right -->
  <!-- steel axle -->
  <link name="front_right_axle">
    <visual>
      <origin rpy="-1.57079632679 0 0" xyz="0 0 0"/>
      <geometry>
        <cylinder length="0.077" radius="0.02"/>
      </geometry>
      <material name="Gray"/>
    </visual>
  </link>
  <joint name="front_right_axle_joint" type="continuous">
    <parent link="base_link"/>
    <child link="front_right_axle"/>
    <origin rpy="0 0 0" xyz="0.15 -0.25 0.0"/>
    <axis rpy="0 0 0" xyz="0 1 0"/>
    <limit effort="100" velocity="100"/>
    <joint_properties damping="0.0" friction="0.0"/>
  </joint>
  <!-- steel rim -->
  <link name="front_right_rim">
    <visual>
      <origin rpy="-1.57079632679 0 0" xyz="0 0 0"/>
      <geometry>
        <cylinder length="0.075" radius="0.09"/>
      </geometry>
      <material name="DarkGray"/>
    </visual>
  </link>
  <joint name="front_right_rim_joint" type="fixed">
    <!-- parent link="${parent}"/-->
    <parent link="front_right_axle"/>
    <child link="front_right_rim"/>
    <origin rpy="0 0 0" xyz="0.15 -0.25 0.0"/>
    <axis rpy="0 0 0" xyz="0 1 0"/>
    <limit effort="100" velocity="100"/>
    <joint_properties damping="0.0" friction="0.0"/>
  </joint>
  <!-- rubber wheel -->
  <link name="front_right_wheel">
    <visual>
      <origin rpy="-1.57079632679 0 0" xyz="0 0 0"/>
      <geometry>
        <cylinder length="0.07" radius="0.13"/>
      </geometry>
      <material name="Yellow"/>
    </visual>
  </link>
  <joint name="front_right_wheel_joint" type="fixed">
    <!-- parent link="${parent}"/-->
    <parent link="front_right_rim"/>
    <child link="front_right_wheel"/>
    <origin rpy="0 0 0" xyz="0.15 -0.25 0.0"/>
    <axis rpy="0 0 0" xyz="0 1 0"/>
    <limit effort="100" velocity="100"/>
    <joint_properties damping="0.0" friction="0.0"/>
  </joint>
  <!--fb : front, back ; lr: left, right -->
  <!-- steel axle -->
  <link name="front_left_axle">
    <visual>
      <origin rpy="-1.57079632679 0 0" xyz="0 0 0"/>
      <geometry>
        <cylinder length="0.077" radius="0.02"/>
      </geometry>
      <material name="Gray"/>
    </visual>
  </link>
  <joint name="front_left_axle_joint" type="continuous">
    <parent link="base_link"/>
    <child link="front_left_axle"/>
    <origin rpy="0 0 0" xyz="0.15 0.25 0.0"/>
    <axis rpy="0 0 0" xyz="0 1 0"/>
    <limit effort="100" velocity="100"/>
    <joint_properties damping="0.0" friction="0.0"/>
  </joint>
  <!-- steel rim -->
  <link name="front_left_rim">
    <visual>
      <origin rpy="-1.57079632679 0 0" xyz="0 0 0"/>
      <geometry>
        <cylinder length="0.075" radius="0.09"/>
      </geometry>
      <material name="DarkGray"/>
    </visual>
  </link>
  <joint name="front_left_rim_joint" type="fixed">
    <!-- parent link="${parent}"/-->
    <parent link="front_left_axle"/>
    <child link="front_left_rim"/>
    <origin rpy="0 0 0" xyz="0.15 0.25 0.0"/>
    <axis rpy="0 0 0" xyz="0 1 0"/>
    <limit effort="100" velocity="100"/>
    <joint_properties damping="0.0" friction="0.0"/>
  </joint>
  <!-- rubber wheel -->
  <link name="front_left_wheel">
    <visual>
      <origin rpy="-1.57079632679 0 0" xyz="0 0 0"/>
      <geometry>
        <cylinder length="0.07" radius="0.13"/>
      </geometry>
      <material name="Yellow"/>
    </visual>
  </link>
  <joint name="front_left_wheel_joint" type="fixed">
    <!-- parent link="${parent}"/-->
    <parent link="front_left_rim"/>
    <child link="front_left_wheel"/>
    <origin rpy="0 0 0" xyz="0.15 0.25 0.0"/>
    <axis rpy="0 0 0" xyz="0 1 0"/>
    <limit effort="100" velocity="100"/>
    <joint_properties damping="0.0" friction="0.0"/>
  </joint>
  <!--fb : front, back ; lr: left, right -->
  <!-- steel axle -->
  <link name="back_right_axle">
    <visual>
      <origin rpy="-1.57079632679 0 0" xyz="0 0 0"/>
      <geometry>
        <cylinder length="0.077" radius="0.02"/>
      </geometry>
      <material name="Gray"/>
    </visual>
  </link>
  <joint name="back_right_axle_joint" type="continuous">
    <parent link="base_link"/>
    <child link="back_right_axle"/>
    <origin rpy="0 0 0" xyz="-0.15 -0.25 0.0"/>
    <axis rpy="0 0 0" xyz="0 1 0"/>
    <limit effort="100" velocity="100"/>
    <joint_properties damping="0.0" friction="0.0"/>
  </joint>
  <!-- steel rim -->
  <link name="back_right_rim">
    <visual>
      <origin rpy="-1.57079632679 0 0" xyz="0 0 0"/>
      <geometry>
        <cylinder length="0.075" radius="0.09"/>
      </geometry>
      <material name="DarkGray"/>
    </visual>
  </link>
  <joint name="back_right_rim_joint" type="fixed">
    <!-- parent link="${parent}"/-->
    <parent link="back_right_axle"/>
    <child link="back_right_rim"/>
    <origin rpy="0 0 0" xyz="-0.15 -0.25 0.0"/>
    <axis rpy="0 0 0" xyz="0 1 0"/>
    <limit effort="100" velocity="100"/>
    <joint_properties damping="0.0" friction="0.0"/>
  </joint>
  <!-- rubber wheel -->
  <link name="back_right_wheel">
    <visual>
      <origin rpy="-1.57079632679 0 0" xyz="0 0 0"/>
      <geometry>
        <cylinder length="0.07" radius="0.13"/>
      </geometry>
      <material name="Yellow"/>
    </visual>
  </link>
  <joint name="back_right_wheel_joint" type="fixed">
    <!-- parent link="${parent}"/-->
    <parent link="back_right_rim"/>
    <child link="back_right_wheel"/>
    <origin rpy="0 0 0" xyz="-0.15 -0.25 0.0"/>
    <axis rpy="0 0 0" xyz="0 1 0"/>
    <limit effort="100" velocity="100"/>
    <joint_properties damping="0.0" friction="0.0"/>
  </joint>
  <!--fb : front, back ; lr: left, right -->
  <!-- steel axle -->
  <link name="back_left_axle">
    <visual>
      <origin rpy="-1.57079632679 0 0" xyz="0 0 0"/>
      <geometry>
        <cylinder length="0.077" radius="0.02"/>
      </geometry>
      <material name="Gray"/>
    </visual>
  </link>
  <joint name="back_left_axle_joint" type="continuous">
    <parent link="base_link"/>
    <child link="back_left_axle"/>
    <origin rpy="0 0 0" xyz="-0.15 0.25 0.0"/>
    <axis rpy="0 0 0" xyz="0 1 0"/>
    <limit effort="100" velocity="100"/>
    <joint_properties damping="0.0" friction="0.0"/>
  </joint>
  <!-- steel rim -->
  <link name="back_left_rim">
    <visual>
      <origin rpy="-1.57079632679 0 0" xyz="0 0 0"/>
      <geometry>
        <cylinder length="0.075" radius="0.09"/>
      </geometry>
      <material name="DarkGray"/>
    </visual>
  </link>
  <joint name="back_left_rim_joint" type="fixed">
    <!-- parent link="${parent}"/-->
    <parent link="back_left_axle"/>
    <child link="back_left_rim"/>
    <origin rpy="0 0 0" xyz="-0.15 0.25 0.0"/>
    <axis rpy="0 0 0" xyz="0 1 0"/>
    <limit effort="100" velocity="100"/>
    <joint_properties damping="0.0" friction="0.0"/>
  </joint>
  <!-- rubber wheel -->
  <link name="back_left_wheel">
    <visual>
      <origin rpy="-1.57079632679 0 0" xyz="0 0 0"/>
      <geometry>
        <cylinder length="0.07" radius="0.13"/>
      </geometry>
      <material name="Yellow"/>
    </visual>
  </link>
  <joint name="back_left_wheel_joint" type="fixed">
    <!-- parent link="${parent}"/-->
    <parent link="back_left_rim"/>
    <child link="back_left_wheel"/>
    <origin rpy="0 0 0" xyz="-0.15 0.25 0.0"/>
    <axis rpy="0 0 0" xyz="0 1 0"/>
    <limit effort="100" velocity="100"/>
    <joint_properties damping="0.0" friction="0.0"/>
  </joint>
  <!--
    ==  RGB joints & links ==
    -->
  <joint name="camera_rgb_joint" type="fixed">
    <origin rpy="0 0 0" xyz="1.0088 0.8966 1.0483"/>
    <parent link="base_link"/>
    <child link="camera_rgb_frame"/>
  </joint>
  <link name="camera_rgb_frame"/>
  <joint name="camera_rgb_optical_joint" type="fixed">
    <origin rpy="-1.57079632679 0 -1.57079632679" xyz="0 0 0"/>
    <parent link="camera_rgb_frame"/>
    <child link="camera_rgb_optical_frame"/>
  </joint>
  <link name="camera_rgb_optical_frame"/>
  <!-- Placing the camera joint -->
  <joint name="camera_joint" type="fixed">
    <origin rpy="0 0 0" xyz="1 1 1"/>
    <parent link="camera_rgb_frame"/>
    <child link="camera_link"/>
  </joint>
  <!-- Mounting the camera at the right position -->
  <link name="camera_link">
    <visual>
      <origin rpy="1.57079632679 0 1.57079632679" xyz="-1.0088 -0.8966 -1.0483"/>
      <geometry>
        <mesh filename="package://realsense_navigation/robot_description/meshes/sensors/r200_entire.dae"/>
      </geometry>
    </visual>
    <collision>
      <origin rpy="0 0 0" xyz="0.0 0.0 0.0"/>
      <geometry>
        <box size="0.130 0.567 0.118"/>
      </geometry>
    </collision>
    <!-- This inertial field needs doesn't contain reliable data!! -->
    <inertial>
      <mass value="0.564"/>
      <origin xyz="0 0 0"/>
      <inertia ixx="0.003881243" ixy="0.0" ixz="0.0" iyy="0.000498940" iyz="0.0" izz="0.003879257"/>
    </inertial>
  </link>
  <!--
    ==  Depth joints & links ==
    -->
  <joint name="camera_depth_joint" type="fixed">
    <origin rpy="0 0 0" xyz="0 0.0274 0"/>
    <parent link="camera_rgb_frame"/>
    <child link="camera_depth_frame"/>
  </joint>
  <link name="camera_depth_frame"/>
  <joint name="camera_depth_optical_joint" type="fixed">
    <origin rpy="-1.57079632679 0 -1.57079632679" xyz="0 0 0"/>
    <parent link="camera_depth_frame"/>
    <child link="camera_depth_optical_frame"/>
  </joint>
  <link name="camera_depth_optical_frame"/>
  <gazebo reference="camera_link">
    <sensor name="camera" type="depth">
      <always_on>true</always_on>
      <update_rate>20.0</update_rate>
      <camera>
        <horizontal_fov>1.0471975512</horizontal_fov>
        <image>
          <format>B8G8R8</format>
          <width>640</width>
          <height>480</height>
        </image>
        <clip>
          <near>0.05</near>
          <far>8.0</far>
        </clip>
      </camera>
      <plugin filename="libgazebo_ros_openni_kinect.so" name="kinect_camera_controller">
        <cameraName>camera</cameraName>
        <alwaysOn>true</alwaysOn>
        <updateRate>10</updateRate>
        <imageTopicName>rgb/image_raw</imageTopicName>
        <depthImageTopicName>depth/image_raw</depthImageTopicName>
        <pointCloudTopicName>depth/points</pointCloudTopicName>
        <cameraInfoTopicName>rgb/camera_info</cameraInfoTopicName>
        <depthImageCameraInfoTopicName>depth/camera_info</depthImageCameraInfoTopicName>
        <frameName>camera_depth_optical_frame</frameName>
        <baseline>0.1</baseline>
        <distortion_k1>0.0</distortion_k1>
        <distortion_k2>0.0</distortion_k2>
        <distortion_k3>0.0</distortion_k3>
        <distortion_t1>0.0</distortion_t1>
        <distortion_t2>0.0</distortion_t2>
        <pointCloudCutoff>0.4</pointCloudCutoff>
      </plugin>
    </sensor>
  </gazebo>
  <!-- 
  <addonbox xbox="0.1" ybox="0.1" zbox="0.1" parent="base_link"/>
  <sensor_r200 parent="base_link"/>
-->
</robot>
