<?xml version="1.0"?>
<robot name="wheel" xmlns:xacro="http://ros.org/wiki/xacro">
  <!-- Last modified by Chrimo at 2017-03-08 15:00 -->

  <!-- Wheels definitions -->
  <xacro:property name="wheel_radius" value="0.13" /> 
  <xacro:property name="rim_radius" value="0.08" /> 
  <xacro:property name="axle_radius" value="0.01" /> 
  <xacro:property name="wheel_height" value="0.070" />
  <xacro:property name="rim_height" value="0.075" />
  <xacro:property name="axle_height" value="0.077" />
  <xacro:property name="wheel_mass" value="1.0" /> <!-- in kg-->
 
  <xacro:property name="base_x_origin_to_wheel_origin" value="0.15" />
  <xacro:property name="base_y_origin_to_wheel_origin" value="0.25" />
  <xacro:property name="base_z_origin_to_wheel_origin" value="0.0" />
 
  <!-- WHEEL MACRO -->
  <xacro:macro name="wheel" params="fb lr parent translateX translateY flipY"> <!--fb : front, back ; lr: left, right -->

    <!-- steel axle -->
    <link name="${fb}_${lr}_axle">
      <visual>
        <origin xyz="0 0 0" rpy="${flipY*M_PI/2} 0 0" /> 
        <geometry>
          <cylinder length="${axle_height}" radius="${axle_radius}" />
        </geometry>
        <material name="Gray" />
      </visual>
    </link>
  
    <joint name="${fb}_${lr}_axle_joint" type="continuous">
      <parent link="${parent}"/>
      <child link="${fb}_${lr}_axle"/>
      <origin xyz="${translateX * base_x_origin_to_wheel_origin} ${translateY * base_y_origin_to_wheel_origin} ${base_z_origin_to_wheel_origin}" rpy="0 0 0" /> 
      <axis xyz="0 1 0" rpy="0 0 0" />
      <limit effort="100" velocity="100"/>
      <joint_properties damping="0.0" friction="0.0"/>
    </joint>

    <!-- steel rim -->
    <link name="${fb}_${lr}_rim">
      <visual>
        <origin xyz="0 0 0" rpy="${flipY*M_PI/2} 0 0" /> 
        <geometry>
          <cylinder length="${rim_height}" radius="${rim_radius}" />
        </geometry>
        <material name="DarkGray" />
      </visual>
    </link>
 
    <joint name="${fb}_${lr}_rim_joint" type="fixed">
      <parent link="${fb}_${lr}_axle"/>
      <child link="${fb}_${lr}_rim"/>
      <origin xyz="0 0 0" rpy="0 0 0" /> 
      <axis xyz="0 1 0" rpy="0 0 0" />
      <limit effort="100" velocity="100"/>
      <joint_properties damping="0.0" friction="0.0"/>
    </joint>

    <!-- rubber wheel -->
    <link name="${fb}_${lr}_wheel">
      <visual>
        <origin xyz="0 0 0" rpy="${flipY*M_PI/2} 0 0" /> 
        <geometry>
          <cylinder length="${wheel_height}" radius="${wheel_radius}" />
        </geometry>
        <material name="Yellow" />
      </visual>
    </link>
  
    <joint name="${fb}_${lr}_wheel_joint" type="fixed">
      <parent link="${fb}_${lr}_rim"/>
      <child link="${fb}_${lr}_wheel"/>
      <origin xyz="0 0 0" rpy="0 0 0" /> 
      <axis xyz="0 1 0" rpy="0 0 0" />
      <limit effort="100" velocity="100"/>
      <joint_properties damping="0.0" friction="0.0"/>
    </joint>
 
  </xacro:macro>
</robot>
